<robot name="onshape">
<link name="wheel">
    <visual>
    <origin xyz="0 0 0" rpy="0 -0 0" />
    <geometry>
    <mesh filename="package://enph353_ros_lab/urdf/wheelsep1/base_plate.stl"/>
    </geometry>
    <material name="base_plate_material">
    <color rgba="0.231373 0.380392 0.705882 1.0"/>
    </material>
    </visual>
    <collision>
    <origin xyz="0 0 0" rpy="0 -0 0" />
    <geometry>
    <mesh filename="package://enph353_ros_lab/urdf/wheelsep1/base_plate.stl"/>
    </geometry>
    <material name="base_plate_material">
    <color rgba="0.231373 0.380392 0.705882 1.0"/>
    </material>
    </collision>
<visual>
<origin xyz="0.0606385 -0.000454 0.153337" rpy="3.14159 -0.753171 3.14159" />
<geometry>
<mesh filename="package://enph353_ros_lab/urdf/wheelsep1/wheel.stl"/>
</geometry>
<material name="wheel_material">
<color rgba="0.615686 0.811765 0.929412 1.0"/>
</material>
</visual>
<collision>
<origin xyz="0.0606385 -0.000454 0.153337" rpy="3.14159 -0.753171 3.14159" />
<geometry>
<mesh filename="package://enph353_ros_lab/urdf/wheelsep1/wheel.stl"/>
</geometry>
<material name="wheel_material">
<color rgba="0.615686 0.811765 0.929412 1.0"/>
</material>
</collision>
<inertial>
<origin xyz="0 -2.04256e-16 0.0886586" rpy="0 0 0"/>
<mass value="0.141446" />
<inertia ixx="0.000141657" ixy="1.14509e-20"  ixz="1.0276e-20" iyy="0.000273959" iyz="3.69159e-22" izz="0.000141657" />
</inertial>
</link>

<link name="stand">
<visual>
<origin xyz="-4.33681e-19 0.0886586 1.38778e-17" rpy="1.5708 -0 0" />
<geometry>
<mesh filename="package://enph353_ros_lab/urdf/wheelsep1/stand.stl"/>
</geometry>
<material name="stand_material">
<color rgba="0.647059 0.647059 0.647059 1.0"/>
</material>
</visual>
<collision>
<origin xyz="-4.33681e-19 0.0886586 1.38778e-17" rpy="1.5708 -0 0" />
<geometry>
<mesh filename="package://enph353_ros_lab/urdf/wheelsep1/stand.stl"/>
</geometry>
<material name="stand_material">
<color rgba="0.647059 0.647059 0.647059 1.0"/>
</material>
</collision>
<inertial>
<origin xyz="-1.28439e-19 0.0406877 1.46998e-17" rpy="0 0 0"/>
<mass value="453.592" />
<inertia ixx="0.50797" ixy="0"  ixz="0" iyy="0.168552" iyz="0" izz="0.342614" />
</inertial>
</link>

<joint name="revolute" type="revolute">
<origin xyz="4.33681e-19 -1.38778e-17 0.0886586" rpy="-1.5708 -0 0" />
<parent link="wheel" />
<child link="stand" />
<axis xyz="0 0 1"/>
<limit effort="1" velocity="20" />
<joint_properties friction="0.0"/>
</joint>


</robot>
