<robot name="wheel">
<link name="part_17">
<visual>
<origin xyz="0.0606385 -0.000454 0.153337" rpy="3.14159 -0.753171 3.14159" />
<geometry>
<mesh filename="home/seanghaeli/catkin_ws/src/wheel/urdf/part_17.stl"/>
</geometry>
<material name="part_17_material">
<color rgba="0.615686 0.811765 0.929412 1.0"/>
</material>
</visual>
<collision>
<origin xyz="0.0606385 -0.000454 0.153337" rpy="3.14159 -0.753171 3.14159" />
<geometry>
<mesh filename="home/seanghaeli/catkin_ws/src/wheel/urdf/part_17.stl"/>
</geometry>
<material name="part_17_material">
<color rgba="0.615686 0.811765 0.929412 1.0"/>
</material>
</collision>
<inertial>
<origin xyz="0 -2.04256e-16 0.0886586" rpy="0 0 0"/>
<mass value="0.141446" />
<inertia ixx="0.000141657" ixy="1.14509e-20"  ixz="2.38286e-20" iyy="0.000273959" iyz="3.69159e-22" izz="0.000141657" />
</inertial>
</link>

<link name="part_2">
<visual>
<origin xyz="-4.33681e-19 0.0886586 1.38778e-17" rpy="1.5708 -0 0" />
<geometry>
<mesh filename="home/seanghaeli/catkin_ws/src/wheel/urdf/part_2.stl"/>
</geometry>
<material name="part_2_material">
<color rgba="0.647059 0.647059 0.647059 1.0"/>
</material>
</visual>
<collision>
<origin xyz="-4.33681e-19 0.0886586 1.38778e-17" rpy="1.5708 -0 0" />
<geometry>
<mesh filename="home/seanghaeli/catkin_ws/src/wheel/urdf/part_2.stl"/>
</geometry>
<material name="part_2_material">
<color rgba="0.647059 0.647059 0.647059 1.0"/>
</material>
</collision>
<inertial>
<origin xyz="-9.31435e-18 0.0781314 4.97248e-17" rpy="0 0 0"/>
<mass value="453.592" />
<inertia ixx="0.572077" ixy="0"  ixz="-1.74341e-16" iyy="2.31536" iyz="2.80694e-16" izz="2.19332" />
</inertial>
</link>

<joint name="revolute" type="revolute">
<origin xyz="4.33681e-19 -1.38778e-17 0.0886586" rpy="-1.5708 -0 0" />
<parent link="part_17" />
<child link="part_2" />
<axis xyz="0 0 1"/>
<limit effort="1" velocity="20" />
<joint_properties friction="0.0"/>
</joint>


</robot>
